<?xml version="1.0" encoding="utf-8"?>
<!-- This URDF was automatically created by SolidWorks to URDF Exporter! Originally created by Stephen Brawner (brawner@gmail.com) 
     Commit Version: 1.6.0-4-g7f85cfe  Build Version: 1.6.7995.38578
     For more information, please see http://wiki.ros.org/sw_urdf_exporter -->
<robot
  name="IHM_finger">
 
  <link
    name="base_link">
    <inertial>
      <origin
        xyz="-0.00073603905102797 -0.124439967353438 0.0163148045871533"
        rpy="0 0 0" />
      <mass
        value="0.257859871104782" />
      <inertia
        ixx="0.000126085881307814"
        ixy="4.49330941225322E-07"
        ixz="-2.4468231651258E-06"
        iyy="0.000301839424292738"
        iyz="-1.8522073924102E-06"
        izz="0.000239672815646621" />
    </inertial>
    <visual>
      <origin
        xyz="0 0 0"
        rpy="0 0 0" />
      <geometry>
        <mesh
          filename="package://IHM_finger/meshes/base_link.STL" />
      </geometry>
      <material
        name="">
        <color
          rgba="0.752941176470588 0.752941176470588 0.752941176470588 1" />
      </material>
    </visual>
    <collision>
      <origin
        xyz="0 0 0"
        rpy="0 0 0" />
      <geometry>
        <mesh
          filename="package://IHM_finger/meshes/base_link.STL" />
      </geometry>
    </collision>
  </link>
  <link
    name="left_finger">
    <inertial>
      <origin
        xyz="-0.0070962 0.07599 -0.00064418"
        rpy="0 0 0" />
      <mass
        value="0.054988" />
      <inertia
        ixx="5.0702E-05"
        ixy="-1.7234E-07"
        ixz="-6.0271E-07"
        iyy="1.0298E-05"
        iyz="-1.0717E-06"
        izz="5.2995E-05" />
    </inertial>
    <visual>
      <origin
        xyz="0 0 0"
        rpy="0 0 0" />
      <geometry>
        <mesh
          filename="package://IHM_finger/meshes/left_finger.STL" />
      </geometry>
      <material
        name="">
        <color
          rgba="0.75294 0.75294 0.75294 1" />
      </material>
    </visual>
    <collision>
      <origin
        xyz="0 0 0"
        rpy="0 0 0" />
      <geometry>
        <mesh
          filename="package://IHM_finger/meshes/left_finger.STL" />
      </geometry>
    </collision>
  </link>
  <joint
    name="joint0"
    type="revolute">
    <origin
      xyz="0.037012 -0.1645 0"
      rpy="2.802 1.5708 0" />
    <parent
      link="base_link" />
    <child
      link="left_finger" />
    <axis
      xyz="1 0 0" />
    <limit
      lower="-3.14"
      upper="3.14"
      effort="10"
      velocity="100" />
  </joint>
  <link
    name="left_insert">
    <inertial>
      <origin
        xyz="0.012 -0.051365 0.011392"
        rpy="0 0 0" />
      <mass
        value="0.027304" />
      <inertia
        ixx="2.6941E-05"
        ixy="-1.2407E-11"
        ixz="-1.0722E-11"
        iyy="2.1544E-06"
        iyz="-1.4064E-07"
        izz="2.7279E-05" />
    </inertial>
    <visual>
      <origin
        xyz="0 0 0"
        rpy="0 0 0" />
      <geometry>
        <mesh
          filename="package://IHM_finger/meshes/left_insert.STL" />
      </geometry>
      <material
        name="">
        <color
          rgba="0.99216 1 0.41961 1" />
      </material>
    </visual>
    <collision>
      <origin
        xyz="0 0 0"
        rpy="0 0 0" />
      <geometry>
        <mesh
          filename="package://IHM_finger/meshes/left_insert.STL" />
      </geometry>
    </collision>
  </link>
  <joint
    name="joint1"
    type="prismatic">
    <origin
      xyz="-0.013495 0.144 0"
      rpy="0 0 0" />
    <parent
      link="left_finger" />
    <child
      link="left_insert" />
    <axis
      xyz="0 0 1" />
    <limit
      lower="-10"
      upper="10"
      effort="15"
      velocity="1" />
  </joint>
  <link
    name="right_finger">
    <inertial>
      <origin
        xyz="-0.002917 0.07599 -0.00064418"
        rpy="0 0 0" />
      <mass
        value="0.054988" />
      <inertia
        ixx="5.0702E-05"
        ixy="-1.7235E-07"
        ixz="-6.0271E-07"
        iyy="1.0298E-05"
        iyz="-1.0717E-06"
        izz="5.2995E-05" />
    </inertial>
    <visual>
      <origin
        xyz="0 0 0"
        rpy="0 0 0" />
      <geometry>
        <mesh
          filename="package://IHM_finger/meshes/right_finger.STL" />
      </geometry>
      <material
        name="">
        <color
          rgba="0.75294 0.75294 0.75294 1" />
      </material>
    </visual>
    <collision>
      <origin
        xyz="0 0 0"
        rpy="0 0 0" />
      <geometry>
        <mesh
          filename="package://IHM_finger/meshes/right_finger.STL" />
      </geometry>
    </collision>
  </link>
  <joint
    name="joint2"
    type="revolute">
    <origin
      xyz="-0.037488 -0.1645 0"
      rpy="0.15466 -1.5708 0" />
    <parent
      link="base_link" />
    <child
      link="right_finger" />
    <axis
      xyz="1 0 0" />
    <limit
      lower="-3.14"
      upper="3.14"
      effort="10"
      velocity="100" />
  </joint>
  <link
    name="right_insert">
    <inertial>
      <origin
        xyz="0.012 -0.051365 0.02879"
        rpy="0 0 0" />
      <mass
        value="0.027304" />
      <inertia
        ixx="2.6941E-05"
        ixy="-1.2405E-11"
        ixz="-1.0716E-11"
        iyy="2.1544E-06"
        iyz="-1.4064E-07"
        izz="2.7279E-05" />
    </inertial>
    <visual>
      <origin
        xyz="0 0 0"
        rpy="0 0 0" />
      <geometry>
        <mesh
          filename="package://IHM_finger/meshes/right_insert.STL" />
      </geometry>
      <material
        name="">
        <color
          rgba="0.99216 1 0.41961 1" />
      </material>
    </visual>
    <collision>
      <origin
        xyz="0 0 0"
        rpy="0 0 0" />
      <geometry>
        <mesh
          filename="package://IHM_finger/meshes/right_insert.STL" />
      </geometry>
    </collision>
  </link>
  <joint
    name="joint3"
    type="prismatic">
    <origin
      xyz="-0.010316 0.144 -0.014597"
      rpy="0 0 0" />
    <parent
      link="right_finger" />
    <child
      link="right_insert" />
    <axis
      xyz="0 0 1" />
    <limit
      lower="-10"
      upper="10"
      effort="15"
      velocity="1" />
  </joint>
</robot>
