<mujoco model="IHM_finger">
  <compiler angle="radian" meshdir="/Users/qiyangyan/Desktop/IHM_finger/IHM_finger/meshes/" autolimits="true"
      balanceinertia="true"
      discardvisual="false"
      />
  <statistic meansize="0.0771609" extent="0.313767" center="0.00508997 -0.163156 0.013906"/>
  
  <asset>
    <mesh name="base_link" file="base_link.STL"/>
    <mesh name="left_finger" file="left_finger.STL"/>
    <mesh name="left_insert" file="left_insert.STL"/>
    <mesh name="right_finger" file="right_finger.STL"/>
    <mesh name="right_insert" file="right_insert.STL"/>
    <texture type="skybox" builtin="gradient" rgb1="0.44 0.85 0.56" rgb2="0.46 0.87 0.58" width="32" height="32"></texture>
    <texture name="robot0:texplane" type="2d" builtin="checker" rgb1="0.2 0.3 0.4" rgb2="0.1 0.15 0.2" width="512" height="512"></texture>
    <texture name="robot0:texgeom" type="cube" builtin="flat" mark="cross" width="127" height="127" rgb1="0.3 0.6 0.5" rgb2="0.3 0.6 0.5" markrgb="0 0 0" random="0.01"></texture>

  </asset>
  
  <!--
  1. joint: name,type,pos,axis,range,damping,armature,user
  2. geom
  -->
  
  <worldbody>
    <body name="base_link" pos="0 0 0"/>
        <geom type="mesh" contype="0" conaffinity="0" group="0" density="0" rgba="1.07 0.84 1.23 1" mesh="base_link"/>
        
        <body name="left_finger" pos="0.037012 -0.1645 0.002" quat="0 0.7071 0 -0.7071">
            <inertial pos="-0.0070962 0.07599 -0.00064418" quat="-0.5 -0.5 0.5 -0.5" mass="0.55" diaginertia="5e-05 5e-05 1e-05" />
            <joint name="joint0" type="hinge" pos="0 0 0" axis="1 0 0" damping="1"/>
            <geom type="mesh" contype="1" conaffinity="1" group="1" density="0" rgba="0.7 0.5 0.5 1" mesh="left_finger"></geom>
            <!-- Use these to label the axis and origin-->
            <geom type="cylinder" fromto="0 0 0 0.03 0 0" size="0.002" rgba="1 0 0 1"/>
            <geom type="cylinder" fromto="0 0 0 0 0.03 0" size="0.002" rgba="0 1 0 1"/>
            <geom type="cylinder" fromto="0 0 0 0 0 0.03" size="0.002" rgba="0 0 1 1"/>
            <geom type="cylinder" pos="-0.0070962 0.07599 -0.00064418" quat="-0.5000 -0.5000 0.5000 -0.5000" size="0.001 0.003" rgba="1 0 0 1"/>
            
            <body name="left_insert" pos="-0.013495 0.144 0">
                <inertial pos="0.012 -0.051365 0.011392" quat="0.5 0.5 -0.5 0.5" mass="0.27" diaginertia="2.72798e-05 2.6941e-05 2.15361e-06"/>
                <joint name="joint1" type="slide" pos="0 0 0" axis="0 0 1" limited="true" range="-0.0017 0.0017" damping="10" stiffness="0"/>
                <geom type="mesh" contype="1" conaffinity="1" group="3" density="0" rgba="1.9 .25 .25 1" mesh="left_insert"/>
            </body>
        </body>
        
        
        <body name="right_finger" pos="-0.037488 -0.1645 0.002" quat="0 0.7071 0 0.7071">
            <inertial pos="-0.002917 0.07599 -0.00064418" quat="0.5 0.5 -0.5 0.5" mass="0.55" diaginertia="5e-05 5e-05 1e-05"/>
            <joint name="joint2" type="hinge" pos="0 0 0" axis="1 0 0" range="-1.0472 1.0472" damping="1"/>
            <geom type="mesh" contype="1" conaffinity="1" group="1" density="0" rgba="0.7 0.5 0.5 1" mesh="right_finger"/>
            <geom type="cylinder" fromto="0 0 0 0.03 0 0" size="0.002" rgba="1 0 0 1"/>
            <geom type="cylinder" fromto="0 0 0 0 0.03 0" size="0.002" rgba="0 1 0 1"/>
            <geom type="cylinder" fromto="0 0 0 0 0 0.03" size="0.002" rgba="0 0 1 1"/>
            <geom type="cylinder" pos="0.0070962 0.07599 -0.00064418" quat="0.5 0.5 -0.5 0.5" size="0.001 0.003" rgba="1 0 0 1"/>
            
            <body name="right_insert" pos="-0.010316 0.144 -0.014597">
                <inertial pos="0.012 -0.051365 0.02879" quat="0.5 0.5 -0.5 0.5" mass="0.27" diaginertia="2.72798e-05 2.6941e-05 2.15361e-06"/>
                <joint name="joint3" type="slide" pos="0 0 0" axis="0 0 1" limited="true" range="-0.0044 0.0011" damping="10" stiffness="0"/>
                <geom type="mesh" contype="1" conaffinity="1" group="2" density="0" rgba="1.9 .25 .25 1" mesh="right_insert"/>
            </body>
        </body>
        
        <light directional="true" diffuse="0.3 0.3 0.3" specular="0.3 0.3 0.3" castshadow="true" pos="-0.5 -0.5 0.5" dir="2 1 -1" ></light>
        <geom type="box" size="2 0.005 2" pos="0 -0.085 0" rgba="0.25 0.22 0.22 1"/>
        <geom type="box" size="0.1 0.01 0.1" pos="0 -0.085 0" rgba="2.11 1.82 1.71 0.9"/>
        <geom condim="3" name="floor" pos="0 0 -0.5" rgba="0.25 0.22 0.22 1" size="2 2 0.125" type="plane"/>
  </worldbody>
  
  <actuator>
      <position name="lf_actuator" joint="joint0" ctrlrange="-0.5 0.5" kp="10" forcerange="-4.785 4.785"/>
      <position name="rf_actuator" joint="joint2" ctrlrange="-0.5 0.5" kp="10" forcerange="-4.785 4.785"/>
      <position name="lf_friction" joint="joint1" ctrlrange="-0.0017 0.0017" kp="100" forcerange="-4.785 4.785"/>
      <position name="rf_friction" joint="joint3" ctrlrange="-0.0044 -0.0011" kp="100" forcerange="-4.785 4.785"/>
  </actuator>
</mujoco>

