<mujoco model="IHM_finger">
  <compiler angle="radian"
      meshdir="/Users/qiyangyan/Desktop/IHM_finger/IHM_finger/meshes/"
      balanceinertia="true"
      discardvisual="false"
      autolimits="true"
      />
      <option solver="PGS" impratio="0.5" cone="elliptic" tolerance="1e-7" noslip_iterations="10000"/>
  <statistic meansize="0.0771609" extent="0.313767" center="0.00508997 -0.163156 0.013906"/>
  
  <asset>
    <mesh name="base_link" file="base_link.STL"/>
    <mesh name="left_finger" file="left_finger.STL"/>
    <mesh name="left_insert" file="left_insert.STL"/>
    <mesh name="right_finger" file="right_finger.STL"/>
    <mesh name="right_insert" file="right_insert.STL"/>
    <texture type="skybox" builtin="gradient" rgb1="0.44 0.85 0.56" rgb2="0.46 0.87 0.58" width="32" height="32"></texture>
    <texture name="robot0:texplane" type="2d" builtin="checker" rgb1="0.2 0.3 0.4" rgb2="0.1 0.15 0.2" width="512" height="512"></texture>
    <texture name="robot0:texgeom" type="cube" builtin="flat" mark="cross" width="127" height="127" rgb1="0.3 0.6 0.5" rgb2="0.3 0.6 0.5" markrgb="0 0 0" random="0.01"></texture>
  </asset>
  
  <default>
      <default class="visual">
          <geom type="mesh" contype="0" conaffinity="0" group="2"/>
      </default>
      <default class="collision">
          <geom type="mesh" group="3"/>
          <default class="left_insert_box">
              <geom mass="0" type="box" pos="0.012 -0.051365 0.0113936"
                  size="0.0121 0.053 0.010375" friction="0.2" solimp="0.95 0.99 0.001" solref="0.004 1" priority="1" rgba="0.9 0.3 0.55 1"/>
          </default>
          <default class="right_insert_box">
              <geom mass="0" type="box" pos="0.012 -0.051365 0.0287911"
                  size="0.0121 0.053 0.010375" friction="0.2" solimp="0.95 0.99 0.001" solref="0.004 1" priority="1" rgba="0.9 0.3 0.55 1"/>
          </default>
          <default class="left_finger_box">
              <geom type="box" size = "0.016 0.06 0.003" contype="1" conaffinity="1" group="4" density="0" rgba="0.96 0.89 1.07 0.7" solimp="0.95 0.99 0.001" solref="0.00001 1" friction = "1" pos="-0.00218 0.087 0.019" priority="1"></geom>
          </default>
          <default class="right_finger_box">
              <geom type="box" size = "0.016 0.06 0.003" contype="1" conaffinity="1" group="4" density="0" rgba="0.96 0.89 1.07 0.7" solimp="0.95 0.99 0.001" solref="0.00001 1" friction = "1"
                  pos="0.00218 0.087 0.019" priority="1"></geom>
          </default>
      </default>
  </default>
  
  <worldbody>
    <body name="base_link" pos="0 0 0"/>
        <geom type="mesh" contype="0" conaffinity="0" group="0" density="0" rgba="1.07 0.84 1.23 1" mesh="base_link"/>
        
        <body name="left_finger" pos="0.037012 -0.1645 0.002" quat="0 0.7071 0 -0.7071">
            <inertial pos="-0.0070962 0.07599 -0.00064418" quat="-0.5 -0.5 0.5 -0.5" mass="0.55" diaginertia="5e-05 5e-05 1e-05" />
            <joint name="joint0" type="hinge" pos="0 0 0" axis="1 0 0" range="-1.0472 1.0472" damping="2" armature="0.005"/>
            <geom type="mesh" contype="1" conaffinity="1" group="1" density="0" rgba="0.5 0.5 0.7 1" friction="1" solimp="1 1 0" solref="0 1" priority="1" mesh="left_finger"  ></geom>
            <geom class="left_finger_box" name="left_finger"/>
            <body name="left_insert" pos="-0.014 0.144 -0.0015">
                <inertial pos="0.012 -0.051365 0.011392" quat="0.5 0.5 -0.5 0.5" mass="0.27" diaginertia="2.72798e-05 2.6941e-05 2.15361e-06"/>
                <joint name="joint1" type="slide" pos="0 0 0" axis="0 0 1" limited="true" range="-0.0017 0.0017" damping="100000" stiffness="0"/>
                <geom class="left_insert_box" name="left_insert"/>
                <geom class="visual" mesh="left_insert" rgba="1.9 1.9 .4 1"/>
            </body>
            
        </body>
        
        <body name="right_finger" pos="-0.037488 -0.1645 0.00181" quat="0 0.7071 0 0.7071">
            <inertial pos="0.0070962 0.07599 -0.00064418" quat="0.5 0.5 -0.5 0.5" mass="0.55" diaginertia="5e-05 5e-05 1e-05"/>
            <joint name="joint2" type="hinge" pos="0 0 0" axis="1 0 0" range="-1.0472 1.0472" damping="2" armature="0.005"/>
            <geom type="mesh" contype="1" conaffinity="1" group="1" density="0" rgba="0.5 0.5 0.7 1" friction="1" solimp="1 1 0" solref="0 1" priority="1" mesh="right_finger"/>
            <geom class="right_finger_box" name="right_finger"/>
            <body name="right_insert" pos="-0.00981 0.144 -0.0188">
                <inertial pos="0.012 -0.051365 0.02879" quat="0.5 0.5 -0.5 0.5" mass="0.27" diaginertia="2.72798e-05 2.6941e-05 2.15361e-06"/>
                <joint name="joint3" type="slide" pos="0 0 0" axis="0 0 1" limited="true" range="-0.0044 0.0011" damping="100000" stiffness="0"/>
                <geom class="right_insert_box" name="right_insert"/>
                <geom class="visual" mesh="right_insert" rgba="1.9 1.9 .4 1"/>
            </body>
        </body>
        
        <body name="object" pos="0 -0.251365 0">
            <freejoint/>
            <geom type="box" size =".015 .015 .025" rgba="1.5 1.5 1.5 1" contype="1" conaffinity="1" friction="1" mass="0.1"/>
        </body>
        
        <light directional="true" diffuse="0.3 0.3 0.3" specular="0.3 0.3 0.3" castshadow="true" pos="0.1 0.1 0.1" dir="0.2 0.1 -0.1" ></light>
        <geom condim="3" name="floor" pos="0 0 -0.5" rgba="0.25 0.22 0.22 1" size="2 2 0.125" type="plane" friction="0"/>
        <geom type="box" size=".2 .2 0.02" pos="0 -0.085 -0.05" rgba="0.25 0.22 0.22 1"/>
  </worldbody>
  
  <actuator>
      <motor name="lf_actuator" joint="joint0" ctrlrange="-1 1" forcerange="-4.785 4.785"></motor>
      <position name="rf_actuator" joint="joint2" ctrlrange="-1.0472 1.0472" kp="5" forcerange="-4.785 4.785"></position>
      <position name="lf_friction" joint="joint1" ctrlrange="0 0.34" gear = "100" kp="20"></position>
      <position name="rf_friction" joint="joint3" ctrlrange="0 0.34" gear = "100" kp="20" >></position>
  </actuator>
</mujoco>


<!-- get axis-->
<!--            <geom type="cylinder" fromto="0 0 0 0.03 0 0" size="0.002" rgba="1 0 0 1"/>-->
<!--            <geom type="cylinder" fromto="0 0 0 0 0.03 0" size="0.002" rgba="0 1 0 1"/>-->
<!--            <geom type="cylinder" fromto="0 0 0 0 0 0.03" size="0.002" rgba="0 0 1 1"/>-->
<!--            <geom type="cylinder" pos="-0.037012 -0.1645 0.002" quat="0 0.7071 0 0.7071" size="0.01 0.04" rgba="1 0 0 1"/>-->
