<mujoco>
    <body name="stand" pos="0 -0.02 0">
        <geom type="box" contype="0" pos="0 -0.03 -0.02" size="0.05 0.05 0.15" conaffinity="0" group="0" density="0" rgba="0.5 0.5 0.7 1" mass="1"></geom>
        <geom type="box" contype="0" pos="0 -0.04 0.023" size="0.04 0.05 0.04" conaffinity="0" group="0" density="0" rgba="2.55 0.80 0 0.8"></geom>
        <geom type="box" contype="0" pos="0 -0.02 0.023" size="0.02 0.05 0.02" conaffinity="0" group="0" density="0" rgba="2.55 0.80 0 0.8"></geom>
        <joint name="joint:stand" type="slide" pos="0 0 0" axis="0 0 1" limited="true" range="0 0.1" damping="100"></joint>
        <body name="base_link" pos="0 0 0">
            <geom type="mesh" contype="0" conaffinity="0" group="0" density="0" rgba="1.07 0.84 1.23 1" mesh="base_link"></geom>
            <body name="left_finger" pos="0.037012 -0.1645 0.002" quat="0 0.7071 0 -0.7071">
                <inertial pos="-0.0070962 0.07599 -0.00064418" quat="-0.5 -0.5 0.5 -0.5" mass="0.55" diaginertia="5e-05 5e-05 1e-05" />
                <joint name="joint:left" type="hinge" pos="0 0 0" axis="1 0 0" range="-1.0472 1.0472" damping="10" armature="0.005"></joint>
                <geom type="mesh" rgba="0.5 0.5 0.7 1" mesh="left_finger"  ></geom>
                <geom class="left_finger_box" name="left_finger"></geom>
                <body name="left_insert" pos="-0.014 0.144 -0.0015">
                    <inertial pos="0.012 -0.051365 0.011392" quat="0.5 0.5 -0.5 0.5" mass="0.27" diaginertia="2.72798e-05 2.6941e-05 2.15361e-06"/>
                    <joint name="joint:leftInsert" type="slide" pos="0 0 0" axis="0 0 1" limited="true" range="-0.0017 0.0017" damping="100000" stiffness="0"></joint>
                    <geom class="left_insert_box" name="left_insert"></geom>
                    <geom class="visual" mesh="left_insert" rgba="1.9 1.9 .4 1"></geom>
                </body>
            </body>
            <body name="right_finger" pos="-0.037488 -0.1645 0.00181" quat="0 0.7071 0 0.7071">
                <inertial pos="0.0070962 0.07599 -0.00064418" quat="0.5 0.5 -0.5 0.5" mass="0.55" diaginertia="5e-05 5e-05 1e-05"/>
                <joint name="joint:right" type="hinge" pos="0 0 0" axis="1 0 0" range="-1.0472 1.0472" damping="10" armature="0.005"></joint>
                <geom type="mesh" rgba="0.5 0.5 0.7 1" mesh="right_finger"></geom>
                <geom class="right_finger_box" name="right_finger"></geom>
                <body name="right_insert" pos="-0.00981 0.144 -0.0188">
                    <inertial pos="0.012 -0.051365 0.02879" quat="0.5 0.5 -0.5 0.5" mass="0.27" diaginertia="2.72798e-05 2.6941e-05 2.15361e-06"/>
                    <joint name="joint:rightInsert" type="slide" pos="0 0 0" axis="0 0 1" limited="true" range="-0.0044 0.0011" damping="100000" stiffness="0"></joint>
                    <geom class="right_insert_box" name="right_insert"></geom>
                    <geom class="visual" mesh="right_insert" rgba="1.9 1.9 .4 1"></geom>
                </body>
            </body>
        </body>
    </body>
</mujoco>
